============================= test session starts ==============================
platform linux -- Python 3.10.1, pytest-6.2.5, py-1.11.0, pluggy-1.0.0 -- /opt/hostedtoolcache/Python/3.10.1/x64/bin/python
cachedir: .pytest_cache
rootdir: /home/runner/work/ASE/ASE
plugins: cov-2.0.0
collecting ... collected 52 items
INTERNALERROR> Traceback (most recent call last):
INTERNALERROR>   File "/opt/hostedtoolcache/Python/3.10.1/x64/lib/python3.10/site-packages/_pytest/main.py", line 269, in wrap_session
INTERNALERROR>     session.exitstatus = doit(config, session) or 0
INTERNALERROR>   File "/opt/hostedtoolcache/Python/3.10.1/x64/lib/python3.10/site-packages/_pytest/main.py", line 322, in _main
INTERNALERROR>     config.hook.pytest_collection(session=session)
INTERNALERROR>   File "/opt/hostedtoolcache/Python/3.10.1/x64/lib/python3.10/site-packages/pluggy/_hooks.py", line 265, in __call__
INTERNALERROR>     return self._hookexec(self.name, self.get_hookimpls(), kwargs, firstresult)
INTERNALERROR>   File "/opt/hostedtoolcache/Python/3.10.1/x64/lib/python3.10/site-packages/pluggy/_manager.py", line 80, in _hookexec
INTERNALERROR>     return self._inner_hookexec(hook_name, methods, kwargs, firstresult)
INTERNALERROR>   File "/opt/hostedtoolcache/Python/3.10.1/x64/lib/python3.10/site-packages/pluggy/_callers.py", line 60, in _multicall
INTERNALERROR>     return outcome.get_result()
INTERNALERROR>   File "/opt/hostedtoolcache/Python/3.10.1/x64/lib/python3.10/site-packages/pluggy/_result.py", line 60, in get_result
INTERNALERROR>     raise ex[1].with_traceback(ex[2])
INTERNALERROR>   File "/opt/hostedtoolcache/Python/3.10.1/x64/lib/python3.10/site-packages/pluggy/_callers.py", line 39, in _multicall
INTERNALERROR>     res = hook_impl.function(*args)
INTERNALERROR>   File "/opt/hostedtoolcache/Python/3.10.1/x64/lib/python3.10/site-packages/_pytest/main.py", line 333, in pytest_collection
INTERNALERROR>     session.perform_collect()
INTERNALERROR>   File "/opt/hostedtoolcache/Python/3.10.1/x64/lib/python3.10/site-packages/_pytest/main.py", line 636, in perform_collect
INTERNALERROR>     self.config.pluginmanager.check_pending()
INTERNALERROR>   File "/opt/hostedtoolcache/Python/3.10.1/x64/lib/python3.10/site-packages/pluggy/_manager.py", line 262, in check_pending
INTERNALERROR>     raise PluginValidationError(
INTERNALERROR> pluggy._manager.PluginValidationError: unknown hook 'pytest_funcarg__cov' in plugin <module 'pytest_cov.plugin' from '/opt/hostedtoolcache/Python/3.10.1/x64/lib/python3.10/site-packages/pytest_cov/plugin.py'>

============================ no tests ran in 0.98s =============================
